2019-12-02 14:27:27,824 ERROR: Exception on /search [GET] [in C:\Users\alexander.danson\AppData\Local\Continuum\anaconda3\lib\site-packages\flask\app.py:1891]
Traceback (most recent call last):
  File "C:\Users\alexander.danson\AppData\Local\Continuum\anaconda3\lib\site-packages\flask\app.py", line 2446, in wsgi_app
    response = self.full_dispatch_request()
  File "C:\Users\alexander.danson\AppData\Local\Continuum\anaconda3\lib\site-packages\flask\app.py", line 1951, in full_dispatch_request
    rv = self.handle_user_exception(e)
  File "C:\Users\alexander.danson\AppData\Local\Continuum\anaconda3\lib\site-packages\flask\app.py", line 1820, in handle_user_exception
    reraise(exc_type, exc_value, tb)
  File "C:\Users\alexander.danson\AppData\Local\Continuum\anaconda3\lib\site-packages\flask\_compat.py", line 39, in reraise
    raise value
  File "C:\Users\alexander.danson\AppData\Local\Continuum\anaconda3\lib\site-packages\flask\app.py", line 1949, in full_dispatch_request
    rv = self.dispatch_request()
  File "C:\Users\alexander.danson\AppData\Local\Continuum\anaconda3\lib\site-packages\flask\app.py", line 1935, in dispatch_request
    return self.view_functions[rule.endpoint](**req.view_args)
  File "C:\Users\alexander.danson\AppData\Local\Continuum\anaconda3\lib\site-packages\flask_login\utils.py", line 261, in decorated_view
    return func(*args, **kwargs)
  File "C:\Users\alexander.danson\Documents\GitHub\microblog\app\main\routes.py", line 130, in search
    current_app.config['POSTS_PER_PAGE'])
  File "C:\Users\alexander.danson\Documents\GitHub\microblog\app\models.py", line 83, in search
    ids, total = query_index(cls.__tablename__, expression, page, per_page)
  File "C:\Users\alexander.danson\Documents\GitHub\microblog\app\search.py", line 22, in query_index
    'from': (page - 1) * per_page, 'size': per_page})
  File "C:\Users\alexander.danson\AppData\Local\Continuum\anaconda3\lib\site-packages\elasticsearch\client\utils.py", line 84, in _wrapped
    return func(*args, params=params, **kwargs)
  File "C:\Users\alexander.danson\AppData\Local\Continuum\anaconda3\lib\site-packages\elasticsearch\client\__init__.py", line 811, in search
    "GET", _make_path(index, "_search"), params=params, body=body
  File "C:\Users\alexander.danson\AppData\Local\Continuum\anaconda3\lib\site-packages\elasticsearch\transport.py", line 358, in perform_request
    timeout=timeout,
  File "C:\Users\alexander.danson\AppData\Local\Continuum\anaconda3\lib\site-packages\elasticsearch\connection\http_urllib3.py", line 257, in perform_request
    self._raise_error(response.status, raw_data)
  File "C:\Users\alexander.danson\AppData\Local\Continuum\anaconda3\lib\site-packages\elasticsearch\connection\base.py", line 182, in _raise_error
    status_code, error_message, additional_info
elasticsearch.exceptions.NotFoundError: NotFoundError(404, 'index_not_found_exception', 'no such index [post]', post, index_or_alias)
2019-12-02 14:28:38,405 INFO: Microblog startup [in C:\Users\alexander.danson\Documents\GitHub\microblog\app\__init__.py:74]
2019-12-02 14:34:12,665 INFO: Microblog startup [in C:\Users\alexander.danson\Documents\GitHub\microblog\app\__init__.py:74]
2020-01-23 11:03:27,475 INFO: Microblog startup [in C:\Users\alexander.danson\Documents\GitHub\microblog\app\__init__.py:74]
